Workbook

Sheet 材料清单
A1: Luciferase Assay Kit 自制 — 试剂材料清单
A2: 注：已按实际采购记录更新（采购行号、供应商货号、包装、数量、单价）。分子量请按实际批次标签核对。
A3: 序号 | B3: 材料名称 | C3: 英文名 / 规格 | D3: CAS 号 | E3: 纯度要求 | F3: 用于 | G3: 供应商货号（实际采购） | H3: 储存条件 | I3: 备注 | J3: 采购行号 | K3: 包装量 | L3: 包装单位 | M3: 采购数量 | N3: UOM | O3: 单价 ($) | P3: 小计 ($)
A4: A | B4: 细胞裂解液 (Cell Lysis Buffer) — 直接购买成品
A5: 1 | B5: Glo Lysis Buffer, 1X (GLB) | C5: Glo Lysis Buffer, 1X, 100 mL | E5: 商品试剂 | F5: 细胞裂解；1X 即用，无需稀释 | G5: PAE2661 | H5: 4 °C（最长可稳定保存 6 个月） | I5: 5分钟快速裂解，无需刮细胞或冻融；萤火虫萤光素酶在 GLB 中室温稳定 ≥48 小时 | J5: 1 | K5: 100 | L5: mL | M5: 5 | N5: EA | O5: 100.62 | P5: =M5*O5 -> 503.1
A6: B | B6: 萤光素酶检测缓冲液 (Luciferase Assay Buffer)
A7: 2 | B7: Tricine | C7: Tricine (N-[Tris(hydroxymethyl)methyl]glycine), 100 g | D7: 5704-04-1 | E7: 99+% | F7: 缓冲体系 pH 7.8 | G7: TS32783-1000 | H7: 室温 | J7: 2 | K7: 100 | L7: g | M7: 1 | N7: EA | O7: 102.75 | P7: =M7*O7 -> 102.75
A8: 3 | B8: 碱式碳酸镁（五水） | C8: Magnesium carbonate hydroxide pentahydrate, 500 g | D8: 39409-82-0 | E8: AR 级 | F8: Mg2+ 来源 | G8: TS44804-5000 | H8: 室温 | I8: 在 Tricine 溶液中缓慢溶解并放出 CO2 | J8: 3 | K8: 500 | L8: g | M8: 1 | N8: EA | O8: 73.51 | P8: =M8*O8 -> 73.51
A9: 4 | B9: 硫酸镁（七水） | C9: Magnesium sulfate heptahydrate, 1 kg | D9: 10034-99-8 | E9: 98+% | F9: Mg2+ 来源 | G9: AAAA14491-0B | H9: 室温 | J9: 4 | K9: 1 | L9: kg | M9: 1 | N9: EA | O9: 72.34 | P9: =M9*O9 -> 72.34
A10: 5 | B10: EDTA 二钠（二水） | C10: EDTA disodium salt dihydrate, 100 g | D10: 6381-92-6 | E10: 分子生物学级 | F10: 螯合杂质金属 | G10: TS32720-1000 | H10: 室温 | J10: 5 | K10: 100 | L10: g | M10: 1 | N10: EA | O10: 66.4 | P10: =M10*O10 -> 66.4
A11: 6a | B11: DTT（Promega） | C11: DTT (Dithiothreitol), 5 g | D11: 3483-12-3 | E11: ≥99% | F11: 检测缓冲液还原剂 | G11: PAV3151 | H11: 2-8 °C 或 -20 °C，干燥 | I11: 溶液易氧化，建议分装冻存 | J11: 6 | K11: 5 | L11: g | M11: 1 | N11: EA | O11: 125.12 | P11: =M11*O11 -> 125.12
A12: 6b | B12: DTT（Ambeed，主用） | C12: DL-Dithiothreitol, 25 g | D12: 3483-12-3 | E12: 按标签 | F12: 检测缓冲液还原剂 | G12: A587635 | H12: 2-8 °C 或 -20 °C，干燥 | I12: 溶液易氧化，建议分装冻存 | J12: 追加2 | K12: 25 | L12: g | M12: 1 | N12: EA | O12: 31.62 | P12: =M12*O12 -> 31.62
A13: 7a | B13: 辅酶 A 三锂盐（VWR，备用/对照） | C13: Coenzyme A trilithium salt, 100 mg | D13: 18439-24-2 | E13: ≥93% | F13: 延长发光（辉光型），提高信号稳定性 | G13: 80051-106 | H13: -20 °C，干燥 | I13: 价格较高；按标签 MW 修正称量 | J13: 7 | K13: 100 | L13: mg | M13: 1 | N13: EA | O13: 331.1 | P13: =M13*O13 -> 331.1
A14: 7b | B14: 辅酶 A 游离酸（Ambeed，主用） | C14: Coenzyme A (free acid), 1 g | D14: 85-61-0 | E14: 按标签（建议 ≥90% HPLC） | F14: 延长发光（辉光型），提高信号稳定性 | G14: A148168 | H14: -20 °C，干燥，密封防潮 | I14: 游离酸偏酸，加入缓冲液后复核 pH 7.8；易吸潮氧化，建议分装 | J14: 追加1 | K14: 1 | L14: g | M14: 1 | N14: EA | O14: 343 | P14: =M14*O14 -> 343
A15: 8 | B15: ATP 二钠盐 | C15: Adenosine 5'-triphosphate (ATP), 5 g | D15: 34369-07-8 | E15: ≥99% | F15: 反应能量来源 | G15: 80050-122 | H15: -20 °C，干燥 | I15: 溶液 pH 偏酸，配好后需复核 pH | J15: 8 | K15: 5 | L15: g | M15: 1 | N15: EA | O15: 109.25 | P15: =M15*O15 -> 109.25
A16: C | B16: 萤光素酶检测底物 (Luciferase Assay Substrate, 冻干)
A17: 9 | B17: D-萤光素钾盐 | C17: D-Luciferin, potassium salt, 5 g | D17: 115144-35-9 | E17: ≥97% | F17: 发光核心底物 | G17: 77567-368 | H17: -20 °C 或 -80 °C，避光、干燥、充氩/氮 | I17: 易溶于水，适合直接分装冻干 | J17: 9 | K17: 5 | L17: g | M17: 1 | N17: EA | O17: 468.31 | P17: =M17*O17 -> 468.31
A18: D | B18: 通用 / 辅助试剂
A19: 10 | B19: 氢氧化钠 | C19: Sodium hydroxide | D19: 1310-73-2 | E19: AR 级 | F19: 调 pH / 游离酸萤光素助溶 | G19: — | H19: 室温，密封 | I19: 本次未采购，使用实验室现有
A20: 11 | B20: 超纯水 | C20: Milli-Q water / Nuclease-free water | D20: 7732-18-5 | E20: 18.2 MΩ·cm | F20: 所有溶液配制 | G20: — | H20: 室温 | I20: 本次未采购，使用实验室现有
A21: E | B21: 报告基因 mRNA（每孔加入）
A22: 12 | B22: Fluc mRNA（Novaprotein） | C22: Firefly luciferase (Fluc) mRNA, 50 mg | E22: 按标签 | F22: 每孔加入 0.1 µg，作为发光报告基因 | G22: （待填） | H22: -80 °C，避免反复冻融 | I22: RNase-free 操作；建议分装 | K22: 50 | L22: mg | M22: 1 | N22: EA | O22: 8750 | P22: =M22*O22 -> 8750
O23: 采购合计 | P23: =SUM(P5:P22) -> 10976.5

Sheet 配方计算
A1: 配方计算 — 修改蓝色输入值，称量量自动计算
A2: 计算：质量 (mg) = 浓度 (mM) × 体积 (mL) × 分子量 (g/mol) ÷ 1000；% v/v 组分按体积计算并折算质量。分子量请按实际购买批次标签修正。
A3: ① 细胞裂解液：Promega Glo Lysis Buffer, 1X (E2661) — 配制时预混进检测缓冲液（仿 ONE-Glo） | I3: 已购 GLB (mL) | J3: 库存是否够用
A4: GLB 使用量 (mL) | B4: 100 | D4: 可检测孔数 | E4: =E7*E30 -> 12000 | F4: 孔 | H4: ★ 唯一主输入：改这里，②③ 全部自动联动 | I4: =材料清单!K5*材料清单!M5 -> 500 | J4: =IF(I4>=B4,"足够","不足") -> 足够
A5: 每孔加入试剂体积 (µL) | B5: 50 | D5: 检测缓冲液 : GLB（体积比） | E5: 5 | F5: 倍 | H5: ="检测缓冲液（①+②）= ② "&TEXT(E29*B23,"#,##0.0")&" mL + GLB "&TEXT(E28*B23,"#,##0.0")&" mL（"&E5&":1）；每孔加 "&B5&" µL" -> 检测缓冲液（①+②）= ② 500.0 mL + GLB 100.0 mL（5:1）；每孔加 50 µL
A6: 每孔含 GLB (µL) | B6: =B5/(1+E5) -> 8.3333333 | D6: 所需检测缓冲液 | E6: =E7*E29*(1+B8) -> 550 | F6: mL | H6: 套数 × 每套 ② 用量 × (1+余量)；自动带入 ② 配制体积
A7: 每孔含 ② 缓冲液 (µL) | B7: =B5-B6 -> 41.666667 | D7: 可分装管数 | E7: =ROUNDDOWN(ROUND(B4/E28,6),0) -> 60 | F7: 管 | H7: GLB 用量 ÷ 每管 GLB；自动带入 ③ 管数
A8: 余量 | B8: 0.1 | D8: 约合 96 孔板数 | E8: =E4/96 -> 125 | F8: 块
A9: ② 萤光素酶检测缓冲液（Luciferase Assay Buffer, 1X，含 ATP / Mg2+ / CoA）
A10: 配制体积 (mL) | B10: =E6 -> 550 | H10: 自动联动 ① 所需检测缓冲液
A11: 组分 | B11: 终浓度 | C11: 单位 | D11: 分子量 (g/mol) | E11: 需称量（按 GLB 用量） | F11: 单位 | H11: 备注 | I11: 已购量 (mg) | J11: 库存是否够用
A12: Tricine | B12: 20 | C12: mM | D12: 179.17 | E12: =B12*$B$10*D12/1000 -> 1970.87 | F12: mg | H12: 第 1 步溶解 | I12: {=材料清单!K7*材料清单!M7*_xlfn.SWITCH(材料清单!L7,"kg",1000000,"g",1000,"mg",1)} -> 100000 | J12: =IF(I12>=E12,"足够","不足") -> 足够
A13: 碱式碳酸镁五水 (MgCO3)4Mg(OH)2·5H2O | B13: 1.07 | C13: mM | D13: 485.65 | E13: =B13*$B$10*D13/1000 -> 285.80503 | F13: mg | H13: 在 Tricine 中搅拌至澄清 | I13: {=材料清单!K8*材料清单!M8*_xlfn.SWITCH(材料清单!L8,"kg",1000000,"g",1000,"mg",1)} -> 500000 | J13: =IF(I13>=E13,"足够","不足") -> 足够
A14: MgSO4·7H2O | B14: 2.67 | C14: mM | D14: 246.47 | E14: =B14*$B$10*D14/1000 -> 361.9412 | F14: mg | I14: {=材料清单!K9*材料清单!M9*_xlfn.SWITCH(材料清单!L9,"kg",1000000,"g",1000,"mg",1)} -> 1000000 | J14: =IF(I14>=E14,"足够","不足") -> 足够
A15: EDTA 二钠二水 | B15: 0.1 | C15: mM | D15: 372.24 | E15: =B15*$B$10*D15/1000 -> 20.4732 | F15: mg | I15: {=材料清单!K10*材料清单!M10*_xlfn.SWITCH(材料清单!L10,"kg",1000000,"g",1000,"mg",1)} -> 100000 | J15: =IF(I15>=E15,"足够","不足") -> 足够
A16: DTT（优先用 Ambeed） | B16: 33.3 | C16: mM | D16: 154.25 | E16: =B16*$B$10*D16/1000 -> 2825.0888 | F16: mg | H16: 调好 pH 后加入 | I16: {=材料清单!K11*材料清单!M11*_xlfn.SWITCH(材料清单!L11,"kg",1000000,"g",1000,"mg",1)+材料清单!K12*材料清单!M12*_xlfn.SWITCH(材料清单!L12,"kg",1000000,"g",1000,"mg",1)} -> 30000 | J16: =IF(I16>=E16,"足够","不足") -> 足够
A17: 辅酶 A 游离酸（Ambeed） | B17: 0.27 | C17: mM | D17: 767.53 | E17: =B17*$B$10*D17/1000 -> 113.97821 | F17: mg | H17: 调好 pH 后加入；游离酸偏酸，加入后复核 pH 7.8；按标签 MW/纯度修正 | I17: {=材料清单!K14*材料清单!M14*_xlfn.SWITCH(材料清单!L14,"kg",1000000,"g",1000,"mg",1)} -> 1000 | J17: =IF(I17>=E17,"足够","不足") -> 足够
A18: ATP 二钠盐（无水计） | B18: 0.53 | C18: mM | D18: 551.14 | E18: =B18*$B$10*D18/1000 -> 160.65731 | F18: mg | H18: 最后加入，复核 pH 7.8 | I18: {=材料清单!K15*材料清单!M15*_xlfn.SWITCH(材料清单!L15,"kg",1000000,"g",1000,"mg",1)} -> 5000 | J18: =IF(I18>=E18,"足够","不足") -> 足够
A19: 超纯水 | B19: 定容至 | C19: — | E19: =$B$10 -> 550 | F19: mL
A20: 目标 pH | B20: 7.8 | H20: 用 NaOH / HCl 微调
A21: ③ D-萤光素：一次性溶于全部检测缓冲液（①+②）后分装，液体 −80 °C 冻存
A22: 每管分装体积 (mL) | B22: 10
A23: 分装管数 | B23: =E7 -> 60 | H23: 自动联动 可分装管数
A24: D-萤光素终浓度 (mM)（在完整试剂中） | B24: 0.47
A25: 冻干前每瓶分装体积 (mL)（直接称量固体时不使用） | B25: 0.5
A26: 组分 | B26: 终浓度 (mM) | D26: 分子量 (g/mol) | E26: 每管含量 (mg) | F26: 总称量 (mg) | G26: 分装母液浓度 (mM)（本方案不使用） | H26: 备注 | I26: 已购量 (mg) | J26: 库存是否够用
A27: D-萤光素钾盐 | B27: =$B$24 -> 0.47 | D27: 318.41 | E27: =B27*$B$22*D27/1000 -> 1.496527 | F27: =E27*$B$23 -> 89.79162 | G27: =B27*$B$22/$B$25 -> 9.4 | H27: 一次称量，直接溶于检测缓冲液 | I27: {=材料清单!K17*材料清单!M17*_xlfn.SWITCH(材料清单!L17,"kg",1000000,"g",1000,"mg",1)} -> 5000 | J27: =IF(I27>=F27,"足够","不足") -> 足够
A28: 每管 GLB 用量 (mL) | E28: =$B$22/(1+$E$5) -> 1.6666667 | F28: mL
A29: 每管 ② 检测缓冲液用量 (mL) | E29: =$B$22-E28 -> 8.3333333 | F29: mL
A30: 每管可测孔数 | E30: =$B$22*1000/$B$5 -> 200 | F30: 孔
A31: ② 缓冲液是否足够 | E31: =IF($B$10>=E29*$B$23,"足够","不足，请增加②体积") -> 足够

Sheet 配制步骤与使用
A1: 配制步骤、使用方法与质控 | B1: ="即用型：①+②+③ 一次性混合后分装 "&配方计算!B23&" 管 × "&配方计算!B22&" mL，每管可测 "&TEXT(配方计算!E30,"#,##0")&" 孔；使用时解冻即用。文中用量自动引用「配方计算」。" -> 即用型：①+②+③ 一次性混合后分装 60 管 × 10 mL，每管可测 200 孔；使用时解冻即用。文中用量自动引用「配方计算」。
A2: 步骤 | B2: 操作说明
A3: ="① 细胞裂解液（Promega Glo Lysis Buffer, 1X, E2661" -> ① 细胞裂解液（Promega Glo Lysis Buffer, 1X, E2661
A4: 1 | B4: ="GLB 为 1X 即用型，无需稀释。本批用量 "&配方计算!B4&" mL，可分装 "&配方计算!B23&" 管，检测约 "&TEXT(配方计算!E4,"#,##0")&" 孔。" -> GLB 为 1X 即用型，无需稀释。本批用量 100 mL，可分装 60 管，检测约 12,000 孔。
A5: 2 | B5: 短期可 4 °C 保存；长期保存可 −20 °C 或 −70 °C 冻存。建议小管分装，融化后平衡至室温、轻柔混匀再用；有效期以瓶签为准。
A6: 3 | B6: ="GLB 不单独加到细胞里：在 ② 第 5 步按 "&配方计算!E5&":1 预混进检测缓冲液（对应 ONE-Glo Assay Buffer 自带裂解成分）。" -> GLB 不单独加到细胞里：在 ② 第 5 步按 5:1 预混进检测缓冲液（对应 ONE-Glo Assay Buffer 自带裂解成分）。
A7: ② 萤光素酶检测缓冲液
A8: 1 | B8: ="目标配制体积 "&TEXT(配方计算!B10,"#,##0")&" mL。先用约 "&TEXT(配方计算!B10*0.8,"#,##0")&" mL（80%）超纯水溶解 Tricine "&TEXT(配方计算!E12/1000,"0.00")&" g。" -> 目标配制体积 550 mL。先用约 440 mL（80%）超纯水溶解 Tricine 1.97 g。
A9: 2 | B9: ="加入碱式碳酸镁五水 "&TEXT(配方计算!E13,"#,##0.0")&" mg，持续搅拌至完全溶解（会释放 CO2，约 15–30 分钟）。" -> 加入碱式碳酸镁五水 285.8 mg，持续搅拌至完全溶解（会释放 CO2，约 15–30 分钟）。
A10: 3 | B10: ="加入 MgSO4·7H2O "&TEXT(配方计算!E14,"#,##0.0")&" mg 和 EDTA 二钠二水 "&TEXT(配方计算!E15,"#,##0.0")&" mg，溶解后用 NaOH / HCl 调 pH 至 "&配方计算!B20&"。" -> 加入 MgSO4·7H2O 361.9 mg 和 EDTA 二钠二水 20.5 mg，溶解后用 NaOH / HCl 调 pH 至 7.8。
A11: 4 | B11: ="依次加入 DTT "&TEXT(配方计算!E16/1000,"0.00")&" g、辅酶 A 游离酸 "&TEXT(配方计算!E17,"#,##0.0")&" mg、ATP 二钠盐 "&TEXT(配方计算!E18,"#,##0.0")&" mg（不耐热，勿加热）。辅酶 A 游离酸偏酸，全部溶解后务必复核 pH "&配方计算!B20&"，再用超纯水定容至 "&TEXT(配方计算!B10,"#,##0")&" mL。" -> 依次加入 DTT 2.83 g、辅酶 A 游离酸 114.0 mg、ATP 二钠盐 160.7 mg（不耐热，勿加热）。辅酶 A 游离酸偏酸，全部溶解后务必复核 pH 7.8，再用超纯水定容至 550 mL。
A12: 5 | B12: ="0.22 µm 过滤后一次性混合：取 ② "&TEXT(配方计算!E29*配方计算!B23,"#,##0.0")&" mL 于大瓶中，加入全部 GLB "&TEXT(配方计算!E28*配方计算!B23,"#,##0.0")&" mL（"&配方计算!E5&":1），轻柔颠倒混匀、避免起泡，得到 "&TEXT(配方计算!B22*配方计算!B23,"#,##0")&" mL 检测缓冲液（①+②）。先不分装，当天直接进行 ③。余下 ② 约 "&TEXT(配方计算!B10-配方计算!E29*配方计算!B23,"#,##0")&" mL 为过滤损耗余量。" -> 0.22 µm 过滤后一次性混合：取 ② 500.0 mL 于大瓶中，加入全部 GLB 100.0 mL（5:1），轻柔颠倒混匀、避免起泡，得到 600 mL 检测缓冲液（①+②）。先不分装，当天直接进行 ③。余下 ② 约 50 mL 为过滤损耗余量。
A13: ③ 加入 D-萤光素并分装
A14: 1 | B14: ="避光操作。用分析天平（0.1 mg）一次称取 D-萤光素钾盐 "&TEXT(配方计算!F27,"#,##0.0")&" mg。" -> 避光操作。用分析天平（0.1 mg）一次称取 D-萤光素钾盐 89.8 mg。
A15: 2 | B15: ="直接加入 ② 第 5 步的 "&TEXT(配方计算!B22*配方计算!B23,"#,##0")&" mL 检测缓冲液中，避光轻柔搅拌或颠倒至完全溶解（终浓度约 "&配方计算!B24&" mM），避免起泡。" -> 直接加入 ② 第 5 步的 600 mL 检测缓冲液中，避光轻柔搅拌或颠倒至完全溶解（终浓度约 0.47 mM），避免起泡。
A16: 3 | B16: ="立即按每管 "&配方计算!B22&" mL 分装 "&配方计算!B23&" 管（棕色或锡箔包裹的离心管），−80 °C 避光冻存，每管一次性使用。" -> 立即按每管 10 mL 分装 60 管（棕色或锡箔包裹的离心管），−80 °C 避光冻存，每管一次性使用。
A17: 4 | B17: ="液体状态稳定性不如固体：建议 1–2 个月内用完，并在第 1、2、4、8 周各取 1 管用阳性对照测信号，确认有效期。" -> 液体状态稳定性不如固体：建议 1–2 个月内用完，并在第 1、2、4、8 周各取 1 管用阳性对照测信号，确认有效期。
A18: 5 | B18: ="成品 = "&配方计算!B23&" 管即用型检测试剂（①+②+③），每管可测 "&TEXT(配方计算!E30,"#,##0")&" 孔（约 "&TEXT(配方计算!E30/96,"0.0")&" 块 96 孔板）。" -> 成品 = 60 管即用型检测试剂（①+②+③），每管可测 200 孔（约 2.1 块 96 孔板）。
A19: ="④ 每次使用（解冻即用，参照 ONE-Glo：试剂与培养基等体积，每孔 "&配方计算!B5&" µL）" -> ④ 每次使用（解冻即用，参照 ONE-Glo：试剂与培养基等体积，每孔 50 µL）
A20: 1 | B20: ="取 1 管，室温避光解冻（或室温水浴），与细胞板一起平衡至室温。细胞种于白色不透明 96 孔板，每孔 "&配方计算!B5&" µL 培养基（与试剂等体积）；若培养体积为 100 µL，检测前先吸去 "&(100-配方计算!B5)&" µL 培养基。" -> 取 1 管，室温避光解冻（或室温水浴），与细胞板一起平衡至室温。细胞种于白色不透明 96 孔板，每孔 50 µL 培养基（与试剂等体积）；若培养体积为 100 µL，检测前先吸去 50 µL 培养基。
A21: 2 | B21: ="解冻后轻柔颠倒混匀（可能轻微分层），无需其他配制。剩余试剂当天弃去，不要再次冻存。" -> 解冻后轻柔颠倒混匀（可能轻微分层），无需其他配制。剩余试剂当天弃去，不要再次冻存。
A22: 3 | B22: ="不吸培养基、不洗细胞，每孔直接加入一步法试剂 "&配方计算!B5&" µL（与培养基等体积）。" -> 不吸培养基、不洗细胞，每孔直接加入一步法试剂 50 µL（与培养基等体积）。
A23: 4 | B23: ="轨道摇床 300–600 rpm 混匀 1–3 分钟，室温孵育至少 3 分钟，使细胞裂解、信号稳定。" -> 轨道摇床 300–600 rpm 混匀 1–3 分钟，室温孵育至少 3 分钟，使细胞裂解、信号稳定。
A24: 5 | B24: ="读取发光值（RLU），积分时间按仪器调整（常用 0.5–1 秒/孔）。同一板内尽量在相同时间窗内读完。" -> 读取发光值（RLU），积分时间按仪器调整（常用 0.5–1 秒/孔）。同一板内尽量在相同时间窗内读完。

Sheet 仪器耗材
A1: 仪器与耗材清单
A2: 类别 | B2: 名称 | C2: 用途 / 要求 | D2: 美国供应商
A3: 仪器 | B3: 化学发光检测仪 / 多功能酶标仪 | C3: 带发光模块，最好配自动进样器 | D3: Promega GloMax；Molecular Devices；Agilent BioTek
A4: 仪器 | B4: 分析天平（0.1 mg / 0.01 mg） | C4: 称量 CoA、ATP、萤光素等微量组分 | D4: Mettler Toledo；Ohaus
A5: 仪器 | B5: pH 计 | C5: 需要准确调至 pH 7.8 | D5: Mettler Toledo；Thermo Scientific Orion
A6: 仪器 | B6: 磁力搅拌器 | C6: 溶解试剂 | D6: Thermo Scientific；Corning；IKA（美国分部）
A7: 仪器 | B7: 真空冷冻干燥机 | C7: 冻干底物；可选，没有时改为 -80 °C 冻存 | D7: Labconco；SP Scientific (VirTis)
A8: 仪器 | B8: -80 °C 与 -20 °C 冰箱 | C8: 保存试剂 | D8: Thermo Scientific；PHCbi；Stirling Ultracold
A9: 仪器 | B9: 水平摇床、微量离心机、移液器 | C9: 裂解与加样 | D9: Eppendorf；Gilson；Rainin；Thermo Scientific
A10: 耗材 | B10: 白色不透明 96 孔板 | C10: 发光检测（降低串扰），细胞培养可用透明板 | D10: Corning (Costar)；Greiner Bio-One；Revvity
A11: 耗材 | B11: 0.22 µm 针头式滤器 / 真空滤杯 | C11: 过滤除菌 | D11: MilliporeSigma；Pall；Thermo Nalgene
A12: 耗材 | B12: 棕色 EP 管 / 冻干瓶（西林瓶+胶塞） | C12: 避光分装 | D12: Eppendorf；Axygen (Corning)；DWK Wheaton（冻干瓶）
A13: 耗材 | B13: 细胞刮、离心管、吸头 | C13: 常规 | D13: Corning；Fisher Scientific；VWR
A14: 耗材 | B14: 氩气或氮气 | C14: 冻干瓶充惰性气体保护萤光素 | D14: Airgas；Praxair/Linde

Sheet 成本核算
A1: 成本核算 — 自制萤光素酶检测试剂 vs Promega ONE-Glo
A2: 蓝色 = 可修改输入；绿色 = 引用其他工作表；黑色 = 公式。自制成本按实际消耗量折算，不含人工、设备和未用完的包装。
A4: ① 结论一览
A5: 自制 · 每孔成本 | C5: ONE-Glo · 每孔成本 | E5: ONE-Glo 是自制的 | G5: 本批可节省
A6: =I38 -> 0.030609582 | C6: =B10/B13+I37 -> 0.6065 | E6: =C6/A6 -> 19.814057 | G6: =G23 -> 6910.685
A7: ="每孔 "&TEXT(B14,"0")&" µL 试剂 + "&B17&" µg Fluc mRNA" -> 每孔 50 µL 试剂 + 0.1 µg Fluc mRNA | C7: ="每盒 "&TEXT(B13,"#,##0")&" 孔（"&B12&" µL/孔）+ "&B17&" µg mRNA" -> 每盒 2,000 孔（50 µL/孔）+ 0.1 µg mRNA | E7: ="按每孔成本计算" -> 按每孔成本计算 | G7: =TEXT(B15,"#,##0")&" 孔，均按实际消耗折算" -> 12,000 孔，均按实际消耗折算
A9: ② 输入参数
A10: ONE-Glo 价格 ($/盒) | B10: 1178 | C10: E6120，100 mL/盒
A11: ONE-Glo 每盒体积 (mL) | B11: 100
A12: ONE-Glo 每孔用量 (µL) | B12: =配方计算!B5 -> 50 | C12: 与自制每孔用量一致（来自「配方计算」），便于同口径对比
A13: ONE-Glo 每盒可测孔数 | B13: =B11*1000/B12 -> 2000 | C13: 体积 × 1000 ÷ 每孔用量
A14: 自制 每孔加入试剂 (µL) | B14: =配方计算!B5 -> 50 | C14: 来自「配方计算」B5（含 GLB + ② + ③）
A15: 本批可检测孔数 | B15: =配方计算!E4 -> 12000 | C15: 来自「配方计算」
A16: VWR CoA 三锂盐分子量 (g/mol) | B16: 785.33 | C16: 用于 ⑤ 货源对比
A17: 每孔 Fluc mRNA 加入量 (µg) | B17: 0.1 | C17: mRNA 两种方案都要用，同时计入自制与 ONE-Glo 每孔成本
A18: ③ 不同检测规模的总成本
A19: 场景 | B19: 检测孔数 | C19: 约合 96 孔板 (块) | D19: 自制试剂成本 ($) | E19: ONE-Glo 需采购盒数（参考） | F19: ONE-Glo 试剂成本 ($) | G19: 节省 ($)
A20: 1 块 96 孔板 | B20: 96 | C20: =B20/96 -> 1 | D20: =B20*$A$6 -> 2.9385199 | E20: =ROUNDUP(B20/$B$13,0) -> 1 | F20: =B20*$C$6 -> 58.224 | G20: =F20-D20 -> 55.28548
A21: 1,000 孔 | B21: 1000 | C21: =B21/96 -> 10.416667 | D21: =B21*$A$6 -> 30.609582 | E21: =ROUNDUP(B21/$B$13,0) -> 1 | F21: =B21*$C$6 -> 606.5 | G21: =F21-D21 -> 575.89042
A22: 10,000 孔 | B22: 10000 | C22: =B22/96 -> 104.16667 | D22: =B22*$A$6 -> 306.09582 | E22: =ROUNDUP(B22/$B$13,0) -> 5 | F22: =B22*$C$6 -> 6065 | G22: =F22-D22 -> 5758.9042
A23: ="本批（"&配方计算!B4&" mL GLB）" -> 本批（100 mL GLB） | B23: =B15 -> 12000 | C23: =B23/96 -> 125 | D23: =B23*$A$6 -> 367.31499 | E23: =ROUNDUP(B23/$B$13,0) -> 6 | F23: =B23*$C$6 -> 7278 | G23: =F23-D23 -> 6910.685
A24: 注：两者均按每孔实际消耗折算（每孔成本 × 孔数），同口径对比；E 列为 ONE-Glo 需采购的整盒数，仅供采购参考。
A26: ④ 自制试剂成本构成（本批）
A27: 组分 | B27: 供应商货号 | C27: 包装 | D27: 单价 ($) | E27: 单位成本 ($/mg 或 $/mL) | F27: 本批用量 | G27: 单位 | H27: 本批成本 ($) | I27: 每孔成本 ($) | J27: 成本占比
A28: Glo Lysis Buffer (GLB) | B28: =材料清单!G5 -> PAE2661 | C28: =材料清单!K5&" "&材料清单!L5 -> 100 mL | D28: =材料清单!O5 -> 100.62 | E28: {=D28/(材料清单!K5*_xlfn.SWITCH(材料清单!L5,"kg",1000000,"g",1000,"mg",1,"mL",1))} -> 1.0062 | F28: =配方计算!B4 -> 100 | G28: =IF(材料清单!L5="mL","mL","mg") -> mL | H28: =E28*F28 -> 100.62 | I28: =H28/$B$15 -> 0.008385 | J28: =H28/$H$38 -> 0.27393383
A29: Tricine | B29: =材料清单!G7 -> TS32783-1000 | C29: =材料清单!K7&" "&材料清单!L7 -> 100 g | D29: =材料清单!O7 -> 102.75 | E29: {=D29/(材料清单!K7*_xlfn.SWITCH(材料清单!L7,"kg",1000000,"g",1000,"mg",1,"mL",1))} -> 0.0010275 | F29: =配方计算!E12 -> 1970.87 | G29: =IF(材料清单!L7="mL","mL","mg") -> mg | H29: =E29*F29 -> 2.0250689 | I29: =H29/$B$15 -> 0.00016875574 | J29: =H29/$H$38 -> 0.0055131672
A30: 碱式碳酸镁五水 | B30: =材料清单!G8 -> TS44804-5000 | C30: =材料清单!K8&" "&材料清单!L8 -> 500 g | D30: =材料清单!O8 -> 73.51 | E30: {=D30/(材料清单!K8*_xlfn.SWITCH(材料清单!L8,"kg",1000000,"g",1000,"mg",1,"mL",1))} -> 0.00014702 | F30: =配方计算!E13 -> 285.80503 | G30: =IF(材料清单!L8="mL","mL","mg") -> mg | H30: =E30*F30 -> 0.042019055 | I30: =H30/$B$15 -> 3.5015879e-06 | J30: =H30/$H$38 -> 0.00011439515
A31: MgSO4·7H2O | B31: =材料清单!G9 -> AAAA14491-0B | C31: =材料清单!K9&" "&材料清单!L9 -> 1 kg | D31: =材料清单!O9 -> 72.34 | E31: {=D31/(材料清单!K9*_xlfn.SWITCH(材料清单!L9,"kg",1000000,"g",1000,"mg",1,"mL",1))} -> 7.234e-05 | F31: =配方计算!E14 -> 361.9412 | G31: =IF(材料清单!L9="mL","mL","mg") -> mg | H31: =E31*F31 -> 0.026182826 | I31: =H31/$B$15 -> 2.1819022e-06 | J31: =H31/$H$38 -> 7.1281671e-05
A32: EDTA 二钠二水 | B32: =材料清单!G10 -> TS32720-1000 | C32: =材料清单!K10&" "&材料清单!L10 -> 100 g | D32: =材料清单!O10 -> 66.4 | E32: {=D32/(材料清单!K10*_xlfn.SWITCH(材料清单!L10,"kg",1000000,"g",1000,"mg",1,"mL",1))} -> 0.000664 | F32: =配方计算!E15 -> 20.4732 | G32: =IF(材料清单!L10="mL","mL","mg") -> mg | H32: =E32*F32 -> 0.013594205 | I32: =H32/$B$15 -> 1.1328504e-06 | J32: =H32/$H$38 -> 3.7009666e-05
A33: DTT（Ambeed） | B33: =材料清单!G12 -> A587635 | C33: =材料清单!K12&" "&材料清单!L12 -> 25 g | D33: =材料清单!O12 -> 31.62 | E33: {=D33/(材料清单!K12*_xlfn.SWITCH(材料清单!L12,"kg",1000000,"g",1000,"mg",1,"mL",1))} -> 0.0012648 | F33: =配方计算!E16 -> 2825.0888 | G33: =IF(材料清单!L12="mL","mL","mg") -> mg | H33: =E33*F33 -> 3.5731723 | I33: =H33/$B$15 -> 0.00029776435 | J33: =H33/$H$38 -> 0.009727815
A34: 辅酶 A 游离酸（Ambeed） | B34: =材料清单!G14 -> A148168 | C34: =材料清单!K14&" "&材料清单!L14 -> 1 g | D34: =材料清单!O14 -> 343 | E34: {=D34/(材料清单!K14*_xlfn.SWITCH(材料清单!L14,"kg",1000000,"g",1000,"mg",1,"mL",1))} -> 0.343 | F34: =配方计算!E17 -> 113.97821 | G34: =IF(材料清单!L14="mL","mL","mg") -> mg | H34: =E34*F34 -> 39.094524 | I34: =H34/$B$15 -> 0.003257877 | J34: =H34/$H$38 -> 0.10643324
A35: ATP 二钠盐（VWR） | B35: =材料清单!G15 -> 80050-122 | C35: =材料清单!K15&" "&材料清单!L15 -> 5 g | D35: =材料清单!O15 -> 109.25 | E35: {=D35/(材料清单!K15*_xlfn.SWITCH(材料清单!L15,"kg",1000000,"g",1000,"mg",1,"mL",1))} -> 0.02185 | F35: =配方计算!E18 -> 160.65731 | G35: =IF(材料清单!L15="mL","mL","mg") -> mg | H35: =E35*F35 -> 3.5103622 | I35: =H35/$B$15 -> 0.00029253019 | J35: =H35/$H$38 -> 0.0095568173
A36: D-萤光素钾盐 | B36: =材料清单!G17 -> 77567-368 | C36: =材料清单!K17&" "&材料清单!L17 -> 5 g | D36: =材料清单!O17 -> 468.31 | E36: {=D36/(材料清单!K17*_xlfn.SWITCH(材料清单!L17,"kg",1000000,"g",1000,"mg",1,"mL",1))} -> 0.093662 | F36: =配方计算!F27 -> 89.79162 | G36: =IF(材料清单!L17="mL","mL","mg") -> mg | H36: =E36*F36 -> 8.4100627 | I36: =H36/$B$15 -> 0.00070083856 | J36: =H36/$H$38 -> 0.022896051
A37: Fluc mRNA（Novaprotein） | B37: =材料清单!G22 -> （待填） | C37: =材料清单!K22&" "&材料清单!L22 -> 50 mg | D37: =材料清单!O22 -> 8750 | E37: {=D37/(材料清单!K22*_xlfn.SWITCH(材料清单!L22,"kg",1000000,"g",1000,"mg",1,"mL",1))} -> 175 | F37: =$B$15*$B$17/1000 -> 1.2 | G37: =IF(材料清单!L22="mL","mL","mg") -> mg | H37: =E37*F37 -> 210 | I37: =H37/$B$15 -> 0.0175 | J37: =H37/$H$38 -> 0.5717164
A38: 合计 | H38: =SUM(H28:H37) -> 367.31499 | I38: =SUM(I28:I37) -> 0.030609582 | J38: =SUM(J28:J37) -> 1
A40: ⑤ 辅酶 A 货源对比（本批）
A41: 货源 | B41: 本批用量 (mg) | C41: 单位成本 ($/mg) | D41: 本批成本 ($) | E41: 每孔成本 ($)
A42: Ambeed 游离酸（现用） | B42: =F34 -> 113.97821 | C42: =E34 -> 0.343 | D42: =H34 -> 39.094524 | E42: =D42/$B$15 -> 0.003257877
A43: VWR 三锂盐（原方案） | B43: =配方计算!B17*配方计算!B10*B16/1000 -> 116.62151 | C43: {=材料清单!O13/(材料清单!K13*_xlfn.SWITCH(材料清单!L13,"kg",1000000,"g",1000,"mg",1))} -> 3.311 | D43: =B43*C43 -> 386.1338 | E43: =D43/$B$15 -> 0.032177817
A44: 改用 Ambeed 节省 | D44: =D43-D42 -> 347.03928 | E44: =E43-E42 -> 0.02891994
...
